<?xml version="1.0"?><robot name="robocat"><link name="frontCylinder"><visual><geometry><cylinder length="1.0" radius="0.2" /></geometry><origin rpy="0.0 -1.507 0.0" xyz="0.7 0.0 0.0" /><material name="gen-mat"><color rgba="1.0 0.0 0.0 1.0" /></material></visual><collision><geometry><cylinder length="1.0" radius="0.2" /></geometry><origin rpy="0.0 -1.507 0.0" xyz="0.7 0.0 0.0" /></collision></link><link name="backCylinder"><visual><geometry><cylinder length="1.0" radius="0.2" /></geometry><origin rpy="0.0 1.507 0.0" xyz="-0.7 0.0 0.0" /><material name="gen-mat"><color rgba="0.0 1.0 0.0 1.0" /></material></visual><collision><geometry><cylinder length="1.0" radius="0.2" /></geometry><origin rpy="0.0 1.507 0.0" xyz="-0.7 0.0 0.0" /></collision><visual><geometry><sphere radius="0.1" /></geometry><material name="gen-mat"><color rgba="0.0 0.0 1.0 1.0" /></material></visual></link><link name="centerSphere" /><joint name="front_to_center" type="revolute"><axis xyz="1 0 0" /><limit effort="0.0" lower="0.0" upper="1.507" velocity="0.5" /><parent link="centerSphere" /><child link="frontCylinder" /><origin xyz="0 0 0" /></joint><joint name="back_to_center" type="revolute"><axis xyz="0 1 0" /><limit effort="0.0" lower="0.0" upper="1.507" velocity="0.5" /><parent link="centerSphere" /><child link="backCylinder" /><origin xyz="0 0 0" /></joint></robot>